Workbook

Sheet JLCPCB Upload
A1: Comment | B1: Designator | C1: Footprint | D1: JLCPCB Part #（optional）
A2: 2.2uF | B2: C15,C16,C21 | C2: C_0402_1005Metric | D2: C307418
A3: 10nF | B3: C17 | C3: C_0402_1005Metric | D3: C15195
A4: 10uF | B4: C32,C37 | C4: C_0402_1005Metric | D4: C15525
A5: 1uF | B5: C2,C3,C4,C5,C11,C12,C13,C14,C18,C38 | C5: C_0402_1005Metric | D5: C52923
A6: 0.1uF | B6: C1,C6,C7,C8,C9,C10,C20,C36 | C6: C_0402_1005Metric | D6: C1525
A7: 47uF | B7: C26 | C7: C_1206_3216Metric | D7: C96123
A8: 4.7uF | B8: C19 | C8: C_0402_1005Metric | D8: C368809
A9: Green LED | B9: D1 | C9: LED_0402_1005Metric | D9: C965794
A10: LED_XL-Z1912RGBA-SG | B10: D4,D5 | C10: LED_XL-Z1912RGBA-SG | D10: C22461785
A11: USB_C | B11: J1 | C11: USB_C_Receptacle_Palconn_UTC16-G | D11: C2927038
A12: U.FL-R-SMT(01) | B12: J7 | C12: HRS_U.FL-R-SMT(01) | D12: C5137195
... A17: 27K 0.1% | B17: R11 | C17: R_0402_1005Metric | D17: C25207446
A18: 33 | B18: R15 | C18: R_0402_1005Metric | D18: C25105
A19: 620 | B19: R2,R18,R24,R36,R38 | C19: R_0402_1005Metric | D19: C4961
A20: 1M | B20: R3,R17,R30 | C20: R_0402_1005Metric | D20: C26083
A21: 470 | B21: R32 | C21: R_0402_1005Metric | D21: C25117
A22: 120 | B22: R33,R34 | C22: R_0402_1005Metric | D22: C25079
A23: 47K | B23: R27,R28,R37,R39 | C23: R_0402_1005Metric | D23: C25792
A24: 10K | B24: R1,R12,R23,R26,R31,R40,R41 | C24: R_0402_1005Metric | D24: C25531
A25: 4.7K | B25: R21,R22 | C25: R_0402_1005Metric | D25: C25900
A26: 100 | B26: R4,R16,R19,R35,R43,R45,R46,R47,R48 | C26: R_0402_1005Metric | D26: C25076
A27: 47 | B27: R5,R13,R14 | C27: R_0402_1005Metric | D27: C25118
A28: 220 | B28: R6 | C28: R_0402_1005Metric | D28: C25091
A29: 374 | B29: R7 | C29: R_0402_1005Metric | D29: C48971914
A30: 13K | B30: R8 | C30: R_0402_1005Metric | D30: C25754
A31: 8.2K 0.1% | B31: R9 | C31: R_0402_1005Metric | D31: C24265089
A32: 100K | B32: R20,R29,R42,R44,R49,R50,R51,R52 | C32: R_0402_1005Metric | D32: C25741
A33: 1K | B33: R53,R54,R55,R56 | C33: R_0402_1005Metric | D33: C11702
A34: TPS22950YBHR | B34: U1,U6,U8,U9,U15 | C34: IC_TPS22950YBHR | D34: C3230039
A35: PAM8904EGPR | B35: U11 | C35: W-QFN2020-12-EP(2x2) | D35: C510550
A36: SN74HCS00BQA-Q1 | B36: U12 | C36: WQFN 14 3.00 mm × 2.50 mm | D36: C4469587
A37: DMP2021UFDF | B37: U13 | C37: Diodes_UDFN2020-6_Type-F | D37: C151459
A38: ISM6HG256XTR | B38: U14 | C38: U_LGA-14L_2p5X3p0X0p83_STM | D38: C51931514
A39: MS5611-01BA | B39: U16 | C39: LGA-8_3x5mm_P1.25mm | D39: C15639
A40: MX25L6436F | B40: U17 | C40: SOP-8_5.28x5.23mm_P1.27mm | D40: C2830754
A41: BQ25185DLHR | B41: U18 | C41: BQ25185DLHR | D41: C19725033
... A47: MMC5983MA | B47: U19 | C47: LGA-16_3x3mm_P0.5mm | D47: C404329

Sheet RocketLocator
A1: Id | B1: Designator | C1: Footprint | D1: Quantity | E1: Comment | F1: JLCPCB Part #（optional） | G1: Type | H1: Unit Cost | I1: Total | J1: Quantity on Hand | K1: Attrition Quantity | L1: Quantity Needed | M1: Gap | N1: Quantity Ordered | O1: Order Status | P1: Lead Time Estimate | Q1: Notes
A2: 1 | B2: C15,C16,C21 | C2: C_0402_1005Metric | D2: 3 | E2: 2.2uF | F2: C307418 | G2: Extended | H2: 0.022 | I2: =RocketLocator[[#This Row],[Quantity]]*RocketLocator[[#This Row],[Unit Cost]] -> 0.066 | J2: 210 | K2: 10 | L2: =IF(AND(RocketLocator[[#This Row],[Quantity]]>0,RocketLocator[[#This Row],[JLCPCB Part '#（optional）]]<>"N/A"),Assumptions!$B$1*RocketLocator[[#This Row],[Quantity]]+RocketLocator[[#This Row],[Attrition Quantity]],0) -> 100 | M2: =IF(RocketLocator[[#This Row],[Quantity Needed]]>RocketLocator[[#This Row],[Quantity on Hand]],RocketLocator[[#This Row],[Quantity Needed]]-RocketLocator[[#This Row],[Quantity on Hand]],"") | Q2: X5R
A3: 2 | B3: C17 | C3: C_0402_1005Metric | D3: 1 | E3: 10nF | F3: C15195 | G3: Basic | H3: 0.0041 | I3: =RocketLocator[[#This Row],[Quantity]]*RocketLocator[[#This Row],[Unit Cost]] -> 0.0041 | J3: 60 | K3: 10 | L3: =IF(AND(RocketLocator[[#This Row],[Quantity]]>0,RocketLocator[[#This Row],[JLCPCB Part '#（optional）]]<>"N/A"),Assumptions!$B$1*RocketLocator[[#This Row],[Quantity]]+RocketLocator[[#This Row],[Attrition Quantity]],0) -> 40 | M3: =IF(RocketLocator[[#This Row],[Quantity Needed]]>RocketLocator[[#This Row],[Quantity on Hand]],RocketLocator[[#This Row],[Quantity Needed]]-RocketLocator[[#This Row],[Quantity on Hand]],"") | Q3: X7R
A4: 3 | B4: C32,C37 | C4: C_0402_1005Metric | D4: 2 | E4: 10uF | F4: C15525 | G4: Basic | H4: 0.0257 | I4: =RocketLocator[[#This Row],[Quantity]]*RocketLocator[[#This Row],[Unit Cost]] -> 0.0514 | J4: 930 | K4: 10 | L4: =IF(AND(RocketLocator[[#This Row],[Quantity]]>0,RocketLocator[[#This Row],[JLCPCB Part '#（optional）]]<>"N/A"),Assumptions!$B$1*RocketLocator[[#This Row],[Quantity]]+RocketLocator[[#This Row],[Attrition Quantity]],0) -> 70 | M4: =IF(RocketLocator[[#This Row],[Quantity Needed]]>RocketLocator[[#This Row],[Quantity on Hand]],RocketLocator[[#This Row],[Quantity Needed]]-RocketLocator[[#This Row],[Quantity on Hand]],"") | Q4: X5R
A5: 4 | B5: C2,C3,C4,C5,C11,C12,C13,C14,C18,C38 | C5: C_0402_1005Metric | D5: 10 | E5: 1uF | F5: C52923 | G5: Basic | H5: 0.0075 | I5: =RocketLocator[[#This Row],[Quantity]]*RocketLocator[[#This Row],[Unit Cost]] -> 0.075 | J5: 480 | K5: 10 | L5: =IF(AND(RocketLocator[[#This Row],[Quantity]]>0,RocketLocator[[#This Row],[JLCPCB Part '#（optional）]]<>"N/A"),Assumptions!$B$1*RocketLocator[[#This Row],[Quantity]]+RocketLocator[[#This Row],[Attrition Quantity]],0) -> 310 | M5: =IF(RocketLocator[[#This Row],[Quantity Needed]]>RocketLocator[[#This Row],[Quantity on Hand]],RocketLocator[[#This Row],[Quantity Needed]]-RocketLocator[[#This Row],[Quantity on Hand]],"") | Q5: X5R
A6: 5 | B6: C1,C6,C7,C8,C9,C10,C20,C36 | C6: C_0402_1005Metric | D6: 8 | E6: 0.1uF | F6: C1525 | G6: Basic | H6: 0.0055 | I6: =RocketLocator[[#This Row],[Quantity]]*RocketLocator[[#This Row],[Unit Cost]] -> 0.044 | J6: 300 | K6: 10 | L6: =IF(AND(RocketLocator[[#This Row],[Quantity]]>0,RocketLocator[[#This Row],[JLCPCB Part '#（optional）]]<>"N/A"),Assumptions!$B$1*RocketLocator[[#This Row],[Quantity]]+RocketLocator[[#This Row],[Attrition Quantity]],0) -> 250 | M6: =IF(RocketLocator[[#This Row],[Quantity Needed]]>RocketLocator[[#This Row],[Quantity on Hand]],RocketLocator[[#This Row],[Quantity Needed]]-RocketLocator[[#This Row],[Quantity on Hand]],"") | Q6: X7R
A7: 6 | B7: C26 | C7: C_1206_3216Metric | D7: 1 | E7: 47uF | F7: C96123 | G7: Basic | H7: 0.168 | I7: =RocketLocator[[#This Row],[Quantity]]*RocketLocator[[#This Row],[Unit Cost]] -> 0.168 | J7: 150 | K7: 4 | L7: =IF(AND(RocketLocator[[#This Row],[Quantity]]>0,RocketLocator[[#This Row],[JLCPCB Part '#（optional）]]<>"N/A"),Assumptions!$B$1*RocketLocator[[#This Row],[Quantity]]+RocketLocator[[#This Row],[Attrition Quantity]],0) -> 34 | M7: =IF(RocketLocator[[#This Row],[Quantity Needed]]>RocketLocator[[#This Row],[Quantity on Hand]],RocketLocator[[#This Row],[Quantity Needed]]-RocketLocator[[#This Row],[Quantity on Hand]],"") | Q7: X5R; JLCPCB now lists as Basic (was Extended)
A8: 7 | B8: C19 | C8: C_0402_1005Metric | D8: 1 | E8: 4.7uF | F8: C368809 | G8: Extended | H8: 0.0157 | I8: =RocketLocator[[#This Row],[Quantity]]*RocketLocator[[#This Row],[Unit Cost]] -> 0.0157 | J8: 500 | L8: =IF(AND(RocketLocator[[#This Row],[Quantity]]>0,RocketLocator[[#This Row],[JLCPCB Part '#（optional）]]<>"N/A"),Assumptions!$B$1*RocketLocator[[#This Row],[Quantity]]+RocketLocator[[#This Row],[Attrition Quantity]],0) -> 30 | M8: =IF(RocketLocator[[#This Row],[Quantity Needed]]>RocketLocator[[#This Row],[Quantity on Hand]],RocketLocator[[#This Row],[Quantity Needed]]-RocketLocator[[#This Row],[Quantity on Hand]],"") | Q8: X5R
A9: 8 | B9: D1 | C9: LED_0402_1005Metric | D9: 1 | E9: Green LED | F9: C965794 | G9: Extended | H9: 0.013 | I9: =RocketLocator[[#This Row],[Quantity]]*RocketLocator[[#This Row],[Unit Cost]] -> 0.013 | J9: 400 | K9: 10 | L9: =IF(AND(RocketLocator[[#This Row],[Quantity]]>0,RocketLocator[[#This Row],[JLCPCB Part '#（optional）]]<>"N/A"),Assumptions!$B$1*RocketLocator[[#This Row],[Quantity]]+RocketLocator[[#This Row],[Attrition Quantity]],0) -> 40 | M9: =IF(RocketLocator[[#This Row],[Quantity Needed]]>RocketLocator[[#This Row],[Quantity on Hand]],RocketLocator[[#This Row],[Quantity Needed]]-RocketLocator[[#This Row],[Quantity on Hand]],"")
A10: 9 | B10: D4,D5 | C10: LED_XL-Z1912RGBA-SG | D10: 2 | E10: LED_XL-Z1912RGBA-SG | F10: C22461785 | G10: Extended | H10: 0.0158 | I10: =RocketLocator[[#This Row],[Quantity]]*RocketLocator[[#This Row],[Unit Cost]] -> 0.0316 | J10: 72 | K10: 4 | L10: =IF(AND(RocketLocator[[#This Row],[Quantity]]>0,RocketLocator[[#This Row],[JLCPCB Part '#（optional）]]<>"N/A"),Assumptions!$B$1*RocketLocator[[#This Row],[Quantity]]+RocketLocator[[#This Row],[Attrition Quantity]],0) -> 64 | M10: =IF(RocketLocator[[#This Row],[Quantity Needed]]>RocketLocator[[#This Row],[Quantity on Hand]],RocketLocator[[#This Row],[Quantity Needed]]-RocketLocator[[#This Row],[Quantity on Hand]],"") | Q10: JLCPCB part is XL-Z1921RGBA-SG; KiCad value/footprint say XL-Z1912RGBA-SG
A11: 10 | B11: H1,H2,H3,H4 | C11: MountingHole_2.2mm_M2 | D11: 4 | E11: MountingHole | F11: N/A | I11: =RocketLocator[[#This Row],[Quantity]]*RocketLocator[[#This Row],[Unit Cost]] -> 0 | L11: =IF(AND(RocketLocator[[#This Row],[Quantity]]>0,RocketLocator[[#This Row],[JLCPCB Part '#（optional）]]<>"N/A"),Assumptions!$B$1*RocketLocator[[#This Row],[Quantity]]+RocketLocator[[#This Row],[Attrition Quantity]],0) -> 0 | M11: =IF(RocketLocator[[#This Row],[Quantity Needed]]>RocketLocator[[#This Row],[Quantity on Hand]],RocketLocator[[#This Row],[Quantity Needed]]-RocketLocator[[#This Row],[Quantity on Hand]],"")
A12: 11 | B12: J1 | C12: USB_C_Receptacle_Palconn_UTC16-G | D12: 1 | E12: USB_C | F12: C2927038 | G12: Extended | H12: 0.0635 | I12: =RocketLocator[[#This Row],[Quantity]]*RocketLocator[[#This Row],[Unit Cost]] -> 0.0635 | J12: 257 | L12: =IF(AND(RocketLocator[[#This Row],[Quantity]]>0,RocketLocator[[#This Row],[JLCPCB Part '#（optional）]]<>"N/A"),Assumptions!$B$1*RocketLocator[[#This Row],[Quantity]]+RocketLocator[[#This Row],[Attrition Quantity]],0) -> 30 | M12: =IF(RocketLocator[[#This Row],[Quantity Needed]]>RocketLocator[[#This Row],[Quantity on Hand]],RocketLocator[[#This Row],[Quantity Needed]]-RocketLocator[[#This Row],[Quantity on Hand]],"")
A13: 12 | B13: J12 | C13: PinHeader_1x04_P2.54mm_Vertical | D13: 1 | E13: Battery / Switch | F13: N/A | I13: =RocketLocator[[#This Row],[Quantity]]*RocketLocator[[#This Row],[Unit Cost]] -> 0 | L13: =IF(AND(RocketLocator[[#This Row],[Quantity]]>0,RocketLocator[[#This Row],[JLCPCB Part '#（optional）]]<>"N/A"),Assumptions!$B$1*RocketLocator[[#This Row],[Quantity]]+RocketLocator[[#This Row],[Attrition Quantity]],0) -> 0 | M13: =IF(RocketLocator[[#This Row],[Quantity Needed]]>RocketLocator[[#This Row],[Quantity on Hand]],RocketLocator[[#This Row],[Quantity Needed]]-RocketLocator[[#This Row],[Quantity on Hand]],"")
A14: 13 | B14: J2 | C14: PinHeader_1x04_P2.54mm_Vertical | D14: 1 | E14: Deploy Ch1 / Ch2 | F14: N/A | I14: =RocketLocator[[#This Row],[Quantity]]*RocketLocator[[#This Row],[Unit Cost]] -> 0 | L14: =IF(AND(RocketLocator[[#This Row],[Quantity]]>0,RocketLocator[[#This Row],[JLCPCB Part '#（optional）]]<>"N/A"),Assumptions!$B$1*RocketLocator[[#This Row],[Quantity]]+RocketLocator[[#This Row],[Attrition Quantity]],0) -> 0 | M14: =IF(RocketLocator[[#This Row],[Quantity Needed]]>RocketLocator[[#This Row],[Quantity on Hand]],RocketLocator[[#This Row],[Quantity Needed]]-RocketLocator[[#This Row],[Quantity on Hand]],"")
A15: 14 | B15: J3 | C15: PinHeader_1x01_P2.54mm_Vertical | D15: 1 | E15: Battery- | F15: N/A | I15: =RocketLocator[[#This Row],[Quantity]]*RocketLocator[[#This Row],[Unit Cost]] -> 0 | L15: =IF(AND(RocketLocator[[#This Row],[Quantity]]>0,RocketLocator[[#This Row],[JLCPCB Part '#（optional）]]<>"N/A"),Assumptions!$B$1*RocketLocator[[#This Row],[Quantity]]+RocketLocator[[#This Row],[Attrition Quantity]],0) -> 0 | M15: =IF(RocketLocator[[#This Row],[Quantity Needed]]>RocketLocator[[#This Row],[Quantity on Hand]],RocketLocator[[#This Row],[Quantity Needed]]-RocketLocator[[#This Row],[Quantity on Hand]],"")
A16: 15 | B16: J4 | C16: PinHeader_1x04_P2.54mm_Vertical | D16: 1 | E16: Deploy Ch3 / Ch4 | F16: N/A | I16: =RocketLocator[[#This Row],[Quantity]]*RocketLocator[[#This Row],[Unit Cost]] -> 0 | L16: =IF(AND(RocketLocator[[#This Row],[Quantity]]>0,RocketLocator[[#This Row],[JLCPCB Part '#（optional）]]<>"N/A"),Assumptions!$B$1*RocketLocator[[#This Row],[Quantity]]+RocketLocator[[#This Row],[Attrition Quantity]],0) -> 0 | M16: =IF(RocketLocator[[#This Row],[Quantity Needed]]>RocketLocator[[#This Row],[Quantity on Hand]],RocketLocator[[#This Row],[Quantity Needed]]-RocketLocator[[#This Row],[Quantity on Hand]],"")
A17: 16 | B17: J7 | C17: HRS_U.FL-R-SMT(01) | D17: 1 | E17: U.FL-R-SMT(01) | F17: C5137195 | G17: Extended | H17: 0.0417 | I17: =RocketLocator[[#This Row],[Quantity]]*RocketLocator[[#This Row],[Unit Cost]] -> 0.0417 | J17: 279 | L17: =IF(AND(RocketLocator[[#This Row],[Quantity]]>0,RocketLocator[[#This Row],[JLCPCB Part '#（optional）]]<>"N/A"),Assumptions!$B$1*RocketLocator[[#This Row],[Quantity]]+RocketLocator[[#This Row],[Attrition Quantity]],0) -> 30 | M17: =IF(RocketLocator[[#This Row],[Quantity Needed]]>RocketLocator[[#This Row],[Quantity on Hand]],RocketLocator[[#This Row],[Quantity Needed]]-RocketLocator[[#This Row],[Quantity on Hand]],"")
A18: 17 | B18: J8 | C18: SAMTEC_FTR-107-51-G-D | D18: 1 | E18: Conn_ST_STDC14 | F18: N/A | I18: =RocketLocator[[#This Row],[Quantity]]*RocketLocator[[#This Row],[Unit Cost]] -> 0 | L18: =IF(AND(RocketLocator[[#This Row],[Quantity]]>0,RocketLocator[[#This Row],[JLCPCB Part '#（optional）]]<>"N/A"),Assumptions!$B$1*RocketLocator[[#This Row],[Quantity]]+RocketLocator[[#This Row],[Attrition Quantity]],0) -> 0 | M18: =IF(RocketLocator[[#This Row],[Quantity Needed]]>RocketLocator[[#This Row],[Quantity on Hand]],RocketLocator[[#This Row],[Quantity Needed]]-RocketLocator[[#This Row],[Quantity on Hand]],"")
A19: 18 | B19: LS1 | C19: PiezoBuzzer | D19: 1 | E19: SPKR | F19: N/A | I19: =RocketLocator[[#This Row],[Quantity]]*RocketLocator[[#This Row],[Unit Cost]] -> 0 | L19: =IF(AND(RocketLocator[[#This Row],[Quantity]]>0,RocketLocator[[#This Row],[JLCPCB Part '#（optional）]]<>"N/A"),Assumptions!$B$1*RocketLocator[[#This Row],[Quantity]]+RocketLocator[[#This Row],[Attrition Quantity]],0) -> 0 | M19: =IF(RocketLocator[[#This Row],[Quantity Needed]]>RocketLocator[[#This Row],[Quantity on Hand]],RocketLocator[[#This Row],[Quantity Needed]]-RocketLocator[[#This Row],[Quantity on Hand]],"")
A20: 19 | B20: Q1 | C20: DFN1006-3L | D20: 1 | E20: 2N7002KN | F20: C49009905 | G20: Extended | H20: 0.0218 | I20: =RocketLocator[[#This Row],[Quantity]]*RocketLocator[[#This Row],[Unit Cost]] -> 0.0218 | J20: 75 | K20: 5 | L20: =IF(AND(RocketLocator[[#This Row],[Quantity]]>0,RocketLocator[[#This Row],[JLCPCB Part '#（optional）]]<>"N/A"),Assumptions!$B$1*RocketLocator[[#This Row],[Quantity]]+RocketLocator[[#This Row],[Attrition Quantity]],0) -> 35 | M20: =IF(RocketLocator[[#This Row],[Quantity Needed]]>RocketLocator[[#This Row],[Quantity on Hand]],RocketLocator[[#This Row],[Quantity Needed]]-RocketLocator[[#This Row],[Quantity on Hand]],"")
A21: 20 | B21: Q3 | C21: DFN1006-3L | D21: 1 | E21: BSS84 | F21: C42394022 | G21: Extended | H21: 0.0403 | I21: =RocketLocator[[#This Row],[Quantity]]*RocketLocator[[#This Row],[Unit Cost]] -> 0.0403 | J21: 42 | K21: 4 | L21: =IF(AND(RocketLocator[[#This Row],[Quantity]]>0,RocketLocator[[#This Row],[JLCPCB Part '#（optional）]]<>"N/A"),Assumptions!$B$1*RocketLocator[[#This Row],[Quantity]]+RocketLocator[[#This Row],[Attrition Quantity]],0) -> 34 | M21: =IF(RocketLocator[[#This Row],[Quantity Needed]]>RocketLocator[[#This Row],[Quantity on Hand]],RocketLocator[[#This Row],[Quantity Needed]]-RocketLocator[[#This Row],[Quantity on Hand]],"")
A22: 21 | B22: Q4,Q5,Q6,Q7 | C22: Nexperia_DFN1010D-3_SOT1215 | D22: 4 | E22: PMXB43UNE | F22: C547273 | G22: Extended | H22: 0.5428 | I22: =RocketLocator[[#This Row],[Quantity]]*RocketLocator[[#This Row],[Unit Cost]] -> 2.1712 | K22: 4 | L22: =IF(AND(RocketLocator[[#This Row],[Quantity]]>0,RocketLocator[[#This Row],[JLCPCB Part '#（optional）]]<>"N/A"),Assumptions!$B$1*RocketLocator[[#This Row],[Quantity]]+RocketLocator[[#This Row],[Attrition Quantity]],0) -> 124 | M22: =IF(RocketLocator[[#This Row],[Quantity Needed]]>RocketLocator[[#This Row],[Quantity on Hand]],RocketLocator[[#This Row],[Quantity Needed]]-RocketLocator[[#This Row],[Quantity on Hand]],"") -> 124 | Q22: New: deploy low-side FETs (Topology A); PMXB43UNEZ, unit cost is LCSC 100+ price (Oct 2026)
A23: 22 | B23: R10,R25 | C23: R_0402_1005Metric | D23: 2 | E23: 5.1K | F23: C294638 | G23: Extended | H23: 0.0014 | I23: =RocketLocator[[#This Row],[Quantity]]*RocketLocator[[#This Row],[Unit Cost]] -> 0.0028 | J23: 2930 | K23: 10 | L23: =IF(AND(RocketLocator[[#This Row],[Quantity]]>0,RocketLocator[[#This Row],[JLCPCB Part '#（optional）]]<>"N/A"),Assumptions!$B$1*RocketLocator[[#This Row],[Quantity]]+RocketLocator[[#This Row],[Attrition Quantity]],0) -> 70 | M23: =IF(RocketLocator[[#This Row],[Quantity Needed]]>RocketLocator[[#This Row],[Quantity on Hand]],RocketLocator[[#This Row],[Quantity Needed]]-RocketLocator[[#This Row],[Quantity on Hand]],"")
A24: 23 | B24: R11 | C24: R_0402_1005Metric | D24: 1 | E24: 27K 0.1% | F24: C25207446 | G24: Extended | H24: 0.0203 | I24: =RocketLocator[[#This Row],[Quantity]]*RocketLocator[[#This Row],[Unit Cost]] -> 0.0203 | J24: 100 | K24: 0 | L24: =IF(AND(RocketLocator[[#This Row],[Quantity]]>0,RocketLocator[[#This Row],[JLCPCB Part '#（optional）]]<>"N/A"),Assumptions!$B$1*RocketLocator[[#This Row],[Quantity]]+RocketLocator[[#This Row],[Attrition Quantity]],0) -> 30 | M24: =IF(RocketLocator[[#This Row],[Quantity Needed]]>RocketLocator[[#This Row],[Quantity on Hand]],RocketLocator[[#This Row],[Quantity Needed]]-RocketLocator[[#This Row],[Quantity on Hand]],"")
A25: 24 | B25: R15 | C25: R_0402_1005Metric | D25: 1 | E25: 33 | F25: C25105 | G25: Basic | H25: 0.0011 | I25: =RocketLocator[[#This Row],[Quantity]]*RocketLocator[[#This Row],[Unit Cost]] -> 0.0011 | J25: 80 | K25: 10 | L25: =IF(AND(RocketLocator[[#This Row],[Quantity]]>0,RocketLocator[[#This Row],[JLCPCB Part '#（optional）]]<>"N/A"),Assumptions!$B$1*RocketLocator[[#This Row],[Quantity]]+RocketLocator[[#This Row],[Attrition Quantity]],0) -> 40 | M25: =IF(RocketLocator[[#This Row],[Quantity Needed]]>RocketLocator[[#This Row],[Quantity on Hand]],RocketLocator[[#This Row],[Quantity Needed]]-RocketLocator[[#This Row],[Quantity on Hand]],"") | Q25: Schematic value 35
A26: 25 | B26: R2,R18,R24,R36,R38 | C26: R_0402_1005Metric | D26: 5 | E26: 620 | F26: C4961 | G26: Extended | H26: 0.0019 | I26: =RocketLocator[[#This Row],[Quantity]]*RocketLocator[[#This Row],[Unit Cost]] -> 0.0095 | J26: 150 | K26: 10 | L26: =IF(AND(RocketLocator[[#This Row],[Quantity]]>0,RocketLocator[[#This Row],[JLCPCB Part '#（optional）]]<>"N/A"),Assumptions!$B$1*RocketLocator[[#This Row],[Quantity]]+RocketLocator[[#This Row],[Attrition Quantity]],0) -> 160 | M26: =IF(RocketLocator[[#This Row],[Quantity Needed]]>RocketLocator[[#This Row],[Quantity on Hand]],RocketLocator[[#This Row],[Quantity Needed]]-RocketLocator[[#This Row],[Quantity on Hand]],"") -> 10
A27: 26 | B27: R3,R17,R30 | C27: R_0402_1005Metric | D27: 3 | E27: 1M | F27: C26083 | G27: Basic | H27: 0.0015 | I27: =RocketLocator[[#This Row],[Quantity]]*RocketLocator[[#This Row],[Unit Cost]] -> 0.0045 | J27: 150 | K27: 10 | L27: =IF(AND(RocketLocator[[#This Row],[Quantity]]>0,RocketLocator[[#This Row],[JLCPCB Part '#（optional）]]<>"N/A"),Assumptions!$B$1*RocketLocator[[#This Row],[Quantity]]+RocketLocator[[#This Row],[Attrition Quantity]],0) -> 100 | M27: =IF(RocketLocator[[#This Row],[Quantity Needed]]>RocketLocator[[#This Row],[Quantity on Hand]],RocketLocator[[#This Row],[Quantity Needed]]-RocketLocator[[#This Row],[Quantity on Hand]],"")
A28: 27 | B28: R32 | C28: R_0402_1005Metric | D28: 1 | E28: 470 | F28: C25117 | G28: Basic | H28: 0.0012 | I28: =RocketLocator[[#This Row],[Quantity]]*RocketLocator[[#This Row],[Unit Cost]] -> 0.0012 | J28: 74 | K28: 10 | L28: =IF(AND(RocketLocator[[#This Row],[Quantity]]>0,RocketLocator[[#This Row],[JLCPCB Part '#（optional）]]<>"N/A"),Assumptions!$B$1*RocketLocator[[#This Row],[Quantity]]+RocketLocator[[#This Row],[Attrition Quantity]],0) -> 40 | M28: =IF(RocketLocator[[#This Row],[Quantity Needed]]>RocketLocator[[#This Row],[Quantity on Hand]],RocketLocator[[#This Row],[Quantity Needed]]-RocketLocator[[#This Row],[Quantity on Hand]],"")
A29: 28 | B29: R33,R34 | C29: R_0402_1005Metric | D29: 2 | E29: 120 | F29: C25079 | G29: Basic | H29: 0.0034 | I29: =RocketLocator[[#This Row],[Quantity]]*RocketLocator[[#This Row],[Unit Cost]] -> 0.0068 | J29: 890 | K29: 10 | L29: =IF(AND(RocketLocator[[#This Row],[Quantity]]>0,RocketLocator[[#This Row],[JLCPCB Part '#（optional）]]<>"N/A"),Assumptions!$B$1*RocketLocator[[#This Row],[Quantity]]+RocketLocator[[#This Row],[Attrition Quantity]],0) -> 70 | M29: =IF(RocketLocator[[#This Row],[Quantity Needed]]>RocketLocator[[#This Row],[Quantity on Hand]],RocketLocator[[#This Row],[Quantity Needed]]-RocketLocator[[#This Row],[Quantity on Hand]],"")
A30: 29 | B30: R27,R28,R37,R39 | C30: R_0402_1005Metric | D30: 4 | E30: 47K | F30: C25792 | G30: Basic | H30: 0.002 | I30: =RocketLocator[[#This Row],[Quantity]]*RocketLocator[[#This Row],[Unit Cost]] -> 0.008 | J30: 150 | K30: 10 | L30: =IF(AND(RocketLocator[[#This Row],[Quantity]]>0,RocketLocator[[#This Row],[JLCPCB Part '#（optional）]]<>"N/A"),Assumptions!$B$1*RocketLocator[[#This Row],[Quantity]]+RocketLocator[[#This Row],[Attrition Quantity]],0) -> 130 | M30: =IF(RocketLocator[[#This Row],[Quantity Needed]]>RocketLocator[[#This Row],[Quantity on Hand]],RocketLocator[[#This Row],[Quantity Needed]]-RocketLocator[[#This Row],[Quantity on Hand]],"")
A31: 30 | B31: R1,R12,R23,R26,R31,R40,R41 | C31: R_0402_1005Metric | D31: 7 | E31: 10K | F31: C25531 | G31: Extended | H31: 0.0026 | I31: =RocketLocator[[#This Row],[Quantity]]*RocketLocator[[#This Row],[Unit Cost]] -> 0.0182 | J31: 9705 | K31: 12 | L31: =IF(AND(RocketLocator[[#This Row],[Quantity]]>0,RocketLocator[[#This Row],[JLCPCB Part '#（optional）]]<>"N/A"),Assumptions!$B$1*RocketLocator[[#This Row],[Quantity]]+RocketLocator[[#This Row],[Attrition Quantity]],0) -> 222 | M31: =IF(RocketLocator[[#This Row],[Quantity Needed]]>RocketLocator[[#This Row],[Quantity on Hand]],RocketLocator[[#This Row],[Quantity Needed]]-RocketLocator[[#This Row],[Quantity on Hand]],"")
A32: 31 | B32: R21,R22 | C32: R_0402_1005Metric | D32: 2 | E32: 4.7K | F32: C25900 | G32: Basic | H32: 0.0021 | I32: =RocketLocator[[#This Row],[Quantity]]*RocketLocator[[#This Row],[Unit Cost]] -> 0.0042 | J32: 970 | K32: 10 | L32: =IF(AND(RocketLocator[[#This Row],[Quantity]]>0,RocketLocator[[#This Row],[JLCPCB Part '#（optional）]]<>"N/A"),Assumptions!$B$1*RocketLocator[[#This Row],[Quantity]]+RocketLocator[[#This Row],[Attrition Quantity]],0) -> 70 | M32: =IF(RocketLocator[[#This Row],[Quantity Needed]]>RocketLocator[[#This Row],[Quantity on Hand]],RocketLocator[[#This Row],[Quantity Needed]]-RocketLocator[[#This Row],[Quantity on Hand]],"")
A33: 32 | B33: R4,R16,R19,R35,R43,R45,R46,R47,R48 | C33: R_0402_1005Metric | D33: 9 | E33: 100 | F33: C25076 | G33: Basic | H33: 0.0012 | I33: =RocketLocator[[#This Row],[Quantity]]*RocketLocator[[#This Row],[Unit Cost]] -> 0.0108 | J33: 960 | K33: 10 | L33: =IF(AND(RocketLocator[[#This Row],[Quantity]]>0,RocketLocator[[#This Row],[JLCPCB Part '#（optional）]]<>"N/A"),Assumptions!$B$1*RocketLocator[[#This Row],[Quantity]]+RocketLocator[[#This Row],[Attrition Quantity]],0) -> 280 | M33: =IF(RocketLocator[[#This Row],[Quantity Needed]]>RocketLocator[[#This Row],[Quantity on Hand]],RocketLocator[[#This Row],[Quantity Needed]]-RocketLocator[[#This Row],[Quantity on Hand]],"") | Q33: Schematic values R16=109, R19=98; R45-R48 are deploy FET gate resistors
A34: 33 | B34: R5,R13,R14 | C34: R_0402_1005Metric | D34: 3 | E34: 47 | F34: C25118 | G34: Extended | H34: 0.0012 | I34: =RocketLocator[[#This Row],[Quantity]]*RocketLocator[[#This Row],[Unit Cost]] -> 0.0036 | J34: 2940 | K34: 12 | L34: =IF(AND(RocketLocator[[#This Row],[Quantity]]>0,RocketLocator[[#This Row],[JLCPCB Part '#（optional）]]<>"N/A"),Assumptions!$B$1*RocketLocator[[#This Row],[Quantity]]+RocketLocator[[#This Row],[Attrition Quantity]],0) -> 102 | M34: =IF(RocketLocator[[#This Row],[Quantity Needed]]>RocketLocator[[#This Row],[Quantity on Hand]],RocketLocator[[#This Row],[Quantity Needed]]-RocketLocator[[#This Row],[Quantity on Hand]],"")
A35: 34 | B35: R6 | C35: R_0402_1005Metric | D35: 1 | E35: 220 | F35: C25091 | G35: Basic | H35: 0.0018 | I35: =RocketLocator[[#This Row],[Quantity]]*RocketLocator[[#This Row],[Unit Cost]] -> 0.0018 | J35: 3030 | K35: 10 | L35: =IF(AND(RocketLocator[[#This Row],[Quantity]]>0,RocketLocator[[#This Row],[JLCPCB Part '#（optional）]]<>"N/A"),Assumptions!$B$1*RocketLocator[[#This Row],[Quantity]]+RocketLocator[[#This Row],[Attrition Quantity]],0) -> 40 | M35: =IF(RocketLocator[[#This Row],[Quantity Needed]]>RocketLocator[[#This Row],[Quantity on Hand]],RocketLocator[[#This Row],[Quantity Needed]]-RocketLocator[[#This Row],[Quantity on Hand]],"") | Q35: Schematic value 218
A36: 35 | B36: R7 | C36: R_0402_1005Metric | D36: 1 | E36: 374 | F36: C48971914 | G36: Extended | H36: 0.0006 | I36: =RocketLocator[[#This Row],[Quantity]]*RocketLocator[[#This Row],[Unit Cost]] -> 0.0006 | J36: 60 | K36: 10 | L36: =IF(AND(RocketLocator[[#This Row],[Quantity]]>0,RocketLocator[[#This Row],[JLCPCB Part '#（optional）]]<>"N/A"),Assumptions!$B$1*RocketLocator[[#This Row],[Quantity]]+RocketLocator[[#This Row],[Attrition Quantity]],0) -> 40 | M36: =IF(RocketLocator[[#This Row],[Quantity Needed]]>RocketLocator[[#This Row],[Quantity on Hand]],RocketLocator[[#This Row],[Quantity Needed]]-RocketLocator[[#This Row],[Quantity on Hand]],"") | Q36: Schematic value 375
A37: 36 | B37: R8 | C37: R_0402_1005Metric | D37: 1 | E37: 13K | F37: C25754 | G37: Extended | H37: 0.0023 | I37: =RocketLocator[[#This Row],[Quantity]]*RocketLocator[[#This Row],[Unit Cost]] -> 0.0023 | J37: 60 | K37: 10 | L37: =IF(AND(RocketLocator[[#This Row],[Quantity]]>0,RocketLocator[[#This Row],[JLCPCB Part '#（optional）]]<>"N/A"),Assumptions!$B$1*RocketLocator[[#This Row],[Quantity]]+RocketLocator[[#This Row],[Attrition Quantity]],0) -> 40 | M37: =IF(RocketLocator[[#This Row],[Quantity Needed]]>RocketLocator[[#This Row],[Quantity on Hand]],RocketLocator[[#This Row],[Quantity Needed]]-RocketLocator[[#This Row],[Quantity on Hand]],"")
A38: 37 | B38: R9 | C38: R_0402_1005Metric | D38: 1 | E38: 8.2K 0.1% | F38: C24265089 | G38: Extended | H38: 0.0213 | I38: =RocketLocator[[#This Row],[Quantity]]*RocketLocator[[#This Row],[Unit Cost]] -> 0.0213 | J38: 100 | K38: 10 | L38: =IF(AND(RocketLocator[[#This Row],[Quantity]]>0,RocketLocator[[#This Row],[JLCPCB Part '#（optional）]]<>"N/A"),Assumptions!$B$1*RocketLocator[[#This Row],[Quantity]]+RocketLocator[[#This Row],[Attrition Quantity]],0) -> 40 | M38: =IF(RocketLocator[[#This Row],[Quantity Needed]]>RocketLocator[[#This Row],[Quantity on Hand]],RocketLocator[[#This Row],[Quantity Needed]]-RocketLocator[[#This Row],[Quantity on Hand]],"")
A39: 38 | B39: R20,R29,R42,R44,R49,R50,R51,R52 | C39: R_0402_1005Metric | D39: 8 | E39: 100K | F39: C25741 | G39: Basic | H39: 0.0015 | I39: =RocketLocator[[#This Row],[Quantity]]*RocketLocator[[#This Row],[Unit Cost]] -> 0.012 | J39: 4960 | K39: 10 | L39: =IF(AND(RocketLocator[[#This Row],[Quantity]]>0,RocketLocator[[#This Row],[JLCPCB Part '#（optional）]]<>"N/A"),Assumptions!$B$1*RocketLocator[[#This Row],[Quantity]]+RocketLocator[[#This Row],[Attrition Quantity]],0) -> 250 | M39: =IF(RocketLocator[[#This Row],[Quantity Needed]]>RocketLocator[[#This Row],[Quantity on Hand]],RocketLocator[[#This Row],[Quantity Needed]]-RocketLocator[[#This Row],[Quantity on Hand]],"") | Q39: R20 was 1M before Topology A; R49-R52 are deploy FET gate pulldowns
A40: 39 | B40: R53,R54,R55,R56 | C40: R_0402_1005Metric | D40: 4 | E40: 1K | F40: C11702 | G40: Basic | H40: 0.0013 | I40: =RocketLocator[[#This Row],[Quantity]]*RocketLocator[[#This Row],[Unit Cost]] -> 0.0052 | K40: 10 | L40: =IF(AND(RocketLocator[[#This Row],[Quantity]]>0,RocketLocator[[#This Row],[JLCPCB Part '#（optional）]]<>"N/A"),Assumptions!$B$1*RocketLocator[[#This Row],[Quantity]]+RocketLocator[[#This Row],[Attrition Quantity]],0) -> 130 | M40: =IF(RocketLocator[[#This Row],[Quantity Needed]]>RocketLocator[[#This Row],[Quantity on Hand]],RocketLocator[[#This Row],[Quantity Needed]]-RocketLocator[[#This Row],[Quantity on Hand]],"") -> 130 | Q40: New: DEPLOY1+..4+ bleeders (Topology A); unit cost is LCSC 100+ price (Oct 2026)
...

Sheet Assumptions
A1: Next production run quantity | B1: 30
A2: Unit cost source | B2: JLCPCB parts API, 2026-10-21; price tier for each row's Quantity Needed (USD)
